

Attempt 1 Error Log:
Traceback (most recent call last):
  File "C:\Users\Rohan\AppData\Local\Programs\Python\Python312\Lib\site-packages\pandas\core\indexes\base.py", line 3805, in get_loc
    return self._engine.get_loc(casted_key)
           ^^^^^^^^^^^^^^^^^^^^^^^^^^^^^^^^
  File "index.pyx", line 167, in pandas._libs.index.IndexEngine.get_loc
  File "index.pyx", line 196, in pandas._libs.index.IndexEngine.get_loc
  File "pandas\\_libs\\hashtable_class_helper.pxi", line 7081, in pandas._libs.hashtable.PyObjectHashTable.get_item
  File "pandas\\_libs\\hashtable_class_helper.pxi", line 7089, in pandas._libs.hashtable.PyObjectHashTable.get_item
KeyError: 'target'

The above exception was the direct cause of the following exception:

Traceback (most recent call last):
  File "c:\Users\Rohan\Desktop\GautamSirIPWork\idea-to-execution-ip\final_code_files\finance_paper_1\temp_train.py", line 71, in <module>
    df = preprocess_data(df.copy(), list_of_ids) # Preprocess the data
         ^^^^^^^^^^^^^^^^^^^^^^^^^^^^^^^^^^^^^^^
  File "c:\Users\Rohan\Desktop\GautamSirIPWork\idea-to-execution-ip\final_code_files\finance_paper_1\temp_train.py", line 53, in preprocess_data
    df['target'] = [int(2 * (score_10 + 1)) for score_10 in df['target']]
                                                            ~~^^^^^^^^^^
  File "C:\Users\Rohan\AppData\Local\Programs\Python\Python312\Lib\site-packages\pandas\core\frame.py", line 4090, in __getitem__
    indexer = self.columns.get_loc(key)
              ^^^^^^^^^^^^^^^^^^^^^^^^^
  File "C:\Users\Rohan\AppData\Local\Programs\Python\Python312\Lib\site-packages\pandas\core\indexes\base.py", line 3812, in get_loc
    raise KeyError(key) from err
KeyError: 'target'
