

Attempt 2 Error Log:
Traceback (most recent call last):
  File "c:\Users\Rohan\Desktop\GautamSirIPWork\idea-to-execution-ip\final_code_files\finance_paper_2\temp_train.py", line 163, in <module>
    X = df.drop(['score_10', 'next_day_direction', 'stock_id'], axis=1).values.tolist()  # Separate numerical features
        ^^^^^^^^^^^^^^^^^^^^^^^^^^^^^^^^^^^^^^^^^^^^^^^^^^^^^^^^^^^^^^^
  File "C:\Users\Rohan\AppData\Local\Programs\Python\Python312\Lib\site-packages\pandas\core\frame.py", line 5568, in drop
    return super().drop(
           ^^^^^^^^^^^^^
  File "C:\Users\Rohan\AppData\Local\Programs\Python\Python312\Lib\site-packages\pandas\core\generic.py", line 4785, in drop
    obj = obj._drop_axis(labels, axis, level=level, errors=errors)
          ^^^^^^^^^^^^^^^^^^^^^^^^^^^^^^^^^^^^^^^^^^^^^^^^^^^^^^^^
  File "C:\Users\Rohan\AppData\Local\Programs\Python\Python312\Lib\site-packages\pandas\core\generic.py", line 4827, in _drop_axis
    new_axis = axis.drop(labels, errors=errors)
               ^^^^^^^^^^^^^^^^^^^^^^^^^^^^^^^^
  File "C:\Users\Rohan\AppData\Local\Programs\Python\Python312\Lib\site-packages\pandas\core\indexes\base.py", line 7070, in drop
    raise KeyError(f"{labels[mask].tolist()} not found in axis")
KeyError: "['score_10', 'next_day_direction', 'stock_id'] not found in axis"
