

Attempt 1 Error Log:
Traceback (most recent call last):
  File "c:\Users\Rohan\Desktop\GautamSirIPWork\idea-to-execution-ip\final_code_files\saveit_input_08_1\temp_train.py", line 38, in <module>
    df = pd.read_csv(training_data_fp) # read data into a pandas datframe
         ^^^^^^^^^^^^^^^^^^^^^^^^^^^^^
  File "C:\Users\Rohan\AppData\Local\Programs\Python\Python312\Lib\site-packages\pandas\io\parsers\readers.py", line 1026, in read_csv
    return _read(filepath_or_buffer, kwds)
           ^^^^^^^^^^^^^^^^^^^^^^^^^^^^^^^
  File "C:\Users\Rohan\AppData\Local\Programs\Python\Python312\Lib\site-packages\pandas\io\parsers\readers.py", line 620, in _read
    parser = TextFileReader(filepath_or_buffer, **kwds)
             ^^^^^^^^^^^^^^^^^^^^^^^^^^^^^^^^^^^^^^^^^^
  File "C:\Users\Rohan\AppData\Local\Programs\Python\Python312\Lib\site-packages\pandas\io\parsers\readers.py", line 1620, in __init__
    self._engine = self._make_engine(f, self.engine)
                   ^^^^^^^^^^^^^^^^^^^^^^^^^^^^^^^^^
  File "C:\Users\Rohan\AppData\Local\Programs\Python\Python312\Lib\site-packages\pandas\io\parsers\readers.py", line 1880, in _make_engine
    self.handles = get_handle(
                   ^^^^^^^^^^^
  File "C:\Users\Rohan\AppData\Local\Programs\Python\Python312\Lib\site-packages\pandas\io\common.py", line 873, in get_handle
    handle = open(
             ^^^^^
FileNotFoundError: [Errno 2] No such file or directory: '/Users/mo/Desktop/repos/idea-to-execution-ip/training_data/df_val_31-May-2024.csv'
